#VRML_SIM R2023b utf8

EXTERNPROTO "https://raw.githubusercontent.com/cyberbotics/webots/R2023b/projects/objects/backgrounds/protos/TexturedBackground.proto"
EXTERNPROTO "https://raw.githubusercontent.com/cyberbotics/webots/R2023b/projects/objects/backgrounds/protos/TexturedBackgroundLight.proto"
EXTERNPROTO "https://raw.githubusercontent.com/cyberbotics/webots/R2023b/projects/objects/floors/protos/CircleArena.proto"
EXTERNPROTO "https://raw.githubusercontent.com/cyberbotics/webots/R2023b/projects/appearances/protos/Plastic.proto"
EXTERNPROTO "https://raw.githubusercontent.com/cyberbotics/webots/R2023b/projects/objects/floors/protos/RectangleArena.proto"

WorldInfo {
  basicTimeStep 16
  contactProperties [
    DEF roda_boba_material ContactProperties {
      material2 "roda_boba_material"
      coulombFriction [
        0
      ]
    }
  ]
}
Viewpoint {
  orientation -0.010467724089735985 -0.9999450100884641 -0.0006352570838273068 4.7754095795316776
  position -0.5274611902099616 3.0405047087478168 4.386281036086801
}
TexturedBackground {
}
TexturedBackgroundLight {
}
Robot {
  translation 0.424994 3.18989 0.055
  rotation 0 0 1 3.1415
  children [
    Gyro {
      translation 0 -0.022 0.033
      lookupTable [
        -10 -10 0.2
        10 10 0.2
      ]
    }
    DistanceSensor {
      translation -0.067 0.0003 0.0012
      rotation 0 0 1 3.141592
      name "distance_sensor2"
      lookupTable [
        0 0 0
        0.3 3000 0.01
      ]
      type "sonar"
    }
    DistanceSensor {
      translation -0.022 -0.05 0
      rotation 0 0 1 -1.5707953071795862
      name "distance_sensor1"
      lookupTable [
        0 0 0
        0.3 3000 0.01
      ]
      type "sonar"
    }
    DistanceSensor {
      translation -0.022 0.05 0
      rotation 0 0 1 1.5707996938995747
      name "distance_sensor3"
      lookupTable [
        0 0 0
        0.3 3000 0.01
      ]
      type "sonar"
    }
    Group {
      children [
        Solid {
          translation -0.06 0 0
          children [
            Pose {
              translation 0.048 -0.013 -0.0133
              rotation 0.5773489358556708 0.5773509358554485 0.5773509358554485 2.0944
              children [
                DEF sensor CadShape {
                  url [
                    "../Parts/Montagem Final 21.10 v7 sensor.obj"
                  ]
                }
              ]
            }
          ]
          name "sensor2"
          boundingObject DEF sensorBO Box {
            size 0.013 0.048 0.031
          }
          physics DEF physics_Sensor Physics {
          }
        }
        Solid {
          translation -0.022 -0.044 0
          rotation 0 0 1 1.5708
          children [
            Pose {
              translation 0.048 -0.013 -0.0133
              rotation 0.5773489358556708 0.5773509358554485 0.5773509358554485 2.0944
              children [
                USE sensor
              ]
            }
          ]
          name "sensor2"
          boundingObject USE sensorBO
          physics USE physics_Sensor
        }
        Solid {
          translation -0.022 0.044 0
          rotation 0 0 1 -1.5707953071795862
          children [
            Pose {
              translation 0.048 -0.013 -0.0133
              rotation 0.5773489358556708 0.5773509358554485 0.5773509358554485 2.0944
              children [
                USE sensor
              ]
            }
          ]
          name "sensor3"
          boundingObject USE sensorBO
          physics USE physics_Sensor
        }
        BallJoint {
          jointParameters BallJointParameters {
            position 13.757583002164036
            anchor -0.027870997249746867 0.0001610450457207897 -0.030606030849649118
          }
          jointParameters2 JointParameters {
            position -2.1403502393353278
            axis 1 0 0
          }
          jointParameters3 JointParameters {
            position -0.5800088470559552
          }
          endPoint Solid {
            translation -0.027870997249746867 0.0001610450457207897 -0.030606030849649118
            rotation 0.479713010376813 -0.6375317226792354 -0.6028505040661923 2.656872226641708
            boundingObject Sphere {
              radius 0.0055
            }
            physics Physics {
            }
          }
        }
        HingeJoint {
          jointParameters HingeJointParameters {
            position 11.658478014229786
            axis 0 -1 0
            anchor 0.0285 0.04044 -0.0181
          }
          device [
            RotationalMotor {
              name "motor_1"
            }
          ]
          endPoint Solid {
            translation 0.0285 0.04044 -0.0181
            rotation 0.8230654516235274 0.40159810601068413 -0.40159958116560585 1.7643005334073492
            children [
              Pose {
                translation -0.0405 0.0046 0.0535
                rotation 0 1 0 1.57
                children [
                  DEF wheel CadShape {
                    url [
                      "../Parts/Montagem Final 21.10 v6 wheel.obj"
                    ]
                  }
                ]
              }
            ]
            name "motor1"
            boundingObject DEF wheelBO Shape {
              appearance PBRAppearance {
                baseColor 0.2 0.2 1
                roughness 1
                metalness 0
              }
              geometry Cylinder {
                height 0.006
                radius 0.017
              }
            }
            physics DEF wheel_physics2 Physics {
            }
          }
        }
        HingeJoint {
          jointParameters HingeJointParameters {
            position 3.8023040531583696
            axis 0 -1 0
            anchor 0.0285 -0.0399 -0.0181
          }
          device [
            RotationalMotor {
              name "motor_2"
            }
          ]
          endPoint Solid {
            translation 0.0285 -0.0399 -0.0181
            rotation -0.23565358558911564 -0.6871929680200484 0.6871922673479309 3.604455609848741
            children [
              Pose {
                translation 0.0404 0.0045 -0.0534
                rotation 0 -1 0 1.57
                children [
                  USE wheel
                ]
              }
            ]
            name "motor2"
            boundingObject USE wheelBO
            physics USE wheel_physics2
          }
        }
        Solid {
          children [
            Pose {
              translation -0.012 -0.013 -0.0135
              rotation 0.5773509358554485 0.5773489358556708 0.5773509358554485 2.0944
              children [
                CadShape {
                  url [
                    "../Parts/Montagem Final 21.10 v10 body.obj"
                  ]
                }
              ]
            }
          ]
          name "body"
          boundingObject DEF shape_body Shape {
            appearance PBRAppearance {
              roughness 1
              metalness 0
            }
            geometry Box {
              size 0.0945 0.07 0.05
            }
          }
          physics Physics {
          }
        }
      ]
    }
  ]
  boundingObject USE shape_body
  physics Physics {
  }
  controller "maze_solution_algorithm"
}
Solid {
  translation -7.36 0 0
  rotation 1 0 0 1.57
  children [
    DEF maze Shape {
      appearance Plastic {
        colorOverride 0.854902 0.854902 0.854902
        type "padded"
        textureTransform TextureTransform {
          center 0.366 0.113
          scale 1.679 1.679
        }
      }
      geometry DEF mazeGeo Mesh {
        url [
          "../Parts/maze1.obj"
        ]
      }
    }
  ]
  name "maze"
  boundingObject USE maze
}
CircleArena {
  translation 2.1 0 0
}
Solid {
  translation 0.28 2.57 0.05
  children [
    RectangleArena {
      translation 0 0 -0.03
      floorSize 2 1.5
    }
    Solid {
      translation -0.875 0 0
      children [
        DEF wallShape Shape {
          appearance Plastic {
            colorOverride 0.682353 0.682353 0.682353
          }
          geometry Box {
            size 0.25 0.01 0.05
          }
        }
      ]
      boundingObject USE wallShape
    }
    Solid {
      translation -0.75 0.125 0
      rotation 0 0 1 1.57
      children [
        USE wallShape
      ]
      name "solid(1)"
      boundingObject USE wallShape
    }
    Solid {
      translation 0.375 -0.5 0
      children [
        USE wallShape
      ]
      name "solid(33)"
      boundingObject USE wallShape
    }
    Solid {
      translation 0.2494 -0.625799 0
      rotation 0 0 1 1.57
      children [
        USE wallShape
      ]
      name "solid(34)"
      boundingObject USE wallShape
    }
    Solid {
      translation -0.75 -0.625 0
      rotation 0 0 1 1.57
      children [
        USE wallShape
      ]
      name "solid(2)"
      boundingObject USE wallShape
    }
    Solid {
      translation -0.75 -0.375 0
      rotation 0 0 1 1.57
      children [
        USE wallShape
      ]
      name "solid(3)"
      boundingObject USE wallShape
    }
    Solid {
      translation -0.625 -0.25 0
      children [
        USE wallShape
      ]
      name "solid(4)"
      boundingObject USE wallShape
    }
    Solid {
      translation -0.500502 -0.6296 0
      rotation 0 0 1 1.57
      children [
        USE wallShape
      ]
      name "solid(5)"
      boundingObject USE wallShape
    }
    Solid {
      translation -0.375 -0.25 0
      children [
        USE wallShape
      ]
      name "solid(6)"
      boundingObject USE wallShape
    }
    Solid {
      translation -0.38 -0.5 0
      children [
        USE wallShape
      ]
      name "solid(7)"
      boundingObject USE wallShape
    }
    Solid {
      translation -0.13 -0.5 0
      children [
        USE wallShape
      ]
      name "solid(8)"
      boundingObject USE wallShape
    }
    Solid {
      translation -0.000294641 -0.37 0
      rotation 0 0 1 1.57
      children [
        USE wallShape
      ]
      name "solid(9)"
      boundingObject USE wallShape
    }
    Solid {
      translation -9.55597e-05 -0.12 0
      rotation 0 0 1 1.57
      children [
        USE wallShape
      ]
      name "solid(10)"
      boundingObject USE wallShape
    }
    Solid {
      translation -0.12 0 0
      children [
        USE wallShape
      ]
      name "solid(11)"
      boundingObject USE wallShape
    }
    Solid {
      translation -0.499896 0.130398 0
      rotation 0 0 1 1.57
      children [
        USE wallShape
      ]
      name "solid(12)"
      boundingObject USE wallShape
    }
    Solid {
      translation -0.5 0.375 0
      rotation 0 0 1 1.57
      children [
        USE wallShape
      ]
      name "solid(13)"
      boundingObject USE wallShape
    }
    Solid {
      translation -0.375 0.5 0
      children [
        USE wallShape
      ]
      name "solid(14)"
      boundingObject USE wallShape
    }
    Solid {
      translation -0.125 0.5 0
      children [
        USE wallShape
      ]
      name "solid(15)"
      boundingObject USE wallShape
    }
    Solid {
      translation -0.625 0.5 0
      children [
        USE wallShape
      ]
      name "solid(16)"
      boundingObject USE wallShape
    }
    Solid {
      translation -0.75 0.625 0
      rotation 0 0 1 1.57
      children [
        USE wallShape
      ]
      name "solid(17)"
      boundingObject USE wallShape
    }
    Solid {
      translation -0.125 0.25 0
      children [
        USE wallShape
      ]
      name "solid(18)"
      boundingObject USE wallShape
    }
    Solid {
      translation 0.125 0.25 0
      children [
        USE wallShape
      ]
      name "solid(19)"
      boundingObject USE wallShape
    }
    Solid {
      translation 0.25 0.375 0
      rotation 0 0 1 1.57
      children [
        USE wallShape
      ]
      name "solid(20)"
      boundingObject USE wallShape
    }
    Solid {
      translation 0.25 0.125 0
      rotation 0 0 1 1.57
      children [
        USE wallShape
      ]
      name "solid(21)"
      boundingObject USE wallShape
    }
    Solid {
      translation 0.25 -0.125 0
      rotation 0 0 1 1.57
      children [
        USE wallShape
      ]
      name "solid(22)"
      boundingObject USE wallShape
    }
    Solid {
      translation 0.375 -0.25 0
      children [
        USE wallShape
      ]
      name "solid(23)"
      boundingObject USE wallShape
    }
    Solid {
      translation 0.625 -0.25 0
      children [
        USE wallShape
      ]
      name "solid(24)"
      boundingObject USE wallShape
    }
    Solid {
      translation 0.75 -0.375 0
      rotation 0 0 1 1.57
      children [
        USE wallShape
      ]
      name "solid(25)"
      boundingObject USE wallShape
    }
    Solid {
      translation 0.875 -0.5 0
      children [
        USE wallShape
      ]
      name "solid(26)"
      boundingObject USE wallShape
    }
    Solid {
      translation 0.5 -0.125 0
      rotation 0 0 1 1.57
      children [
        USE wallShape
      ]
      name "solid(27)"
      boundingObject USE wallShape
    }
    Solid {
      translation 0.625 0 0
      children [
        USE wallShape
      ]
      name "solid(28)"
      boundingObject USE wallShape
    }
    Solid {
      translation 0.75 0.125 0
      rotation 0 0 1 1.57
      children [
        USE wallShape
      ]
      name "solid(29)"
      boundingObject USE wallShape
    }
    Solid {
      translation 0.75 0.375 0
      rotation 0 0 1 1.57
      children [
        USE wallShape
      ]
      name "solid(30)"
      boundingObject USE wallShape
    }
    Solid {
      translation 0.5 0.625 0
      rotation 0 0 1 1.57
      children [
        USE wallShape
      ]
      name "solid(31)"
      boundingObject USE wallShape
    }
    Solid {
      translation 0.5 0.375 0
      rotation 0 0 1 1.57
      children [
        USE wallShape
      ]
      name "solid(32)"
      boundingObject USE wallShape
    }
  ]
}
